import discord
import asyncio
import os
import sys
import traceback
from discord.ext import commands


class ErrorHandler(commands.Cog):
    def __init__(self, bot: commands.Bot):
        self.bot = bot

    @commands.Cog.listener()
    async def on_command_error(self, ctx, error):
        # if command has local error handler, return
        if hasattr(ctx.command, 'on_error'):
            return

        # get the original exception
        error = getattr(error, 'original', error)

        if isinstance(error, commands.CommandNotFound):
            return

        if isinstance(error, commands.BotMissingPermissions):
            print(error.missing_permissions)
            missing = [perm.replace('_', ' ').replace('guild', 'server').title() for perm in error.missing_permissions]
            print(missing)
            if len(missing) > 2:
                fmt = '{}, and {}'.format("**, **".join(missing[:-1]), missing[-1])
            else:
                fmt = ' and '.join(missing)
            _message = 'I need the **{}** permission(s) to run this command.'.format(fmt)
            await ctx.send(_message)
            return

        if isinstance(error, commands.DisabledCommand):
            await ctx.send('This command has been disabled.')
            return

        if isinstance(error, commands.CommandOnCooldown):
            cooldown_msg = await ctx.send(f"{ctx.author.mention} {round(error.retry_after, 2)}s wait and try again!")
            await asyncio.sleep(round(error.retry_after, 2))
            await cooldown_msg.delete()
            return

        if isinstance(error, commands.MissingPermissions):
            missing = [perm.replace('_', ' ').replace('guild', 'server').title() for perm in error.missing_permissions]
            if len(missing) > 2:
                fmt = '{}, and {}'.format("**, **".join(missing[:-1]), missing[-1])
            else:
                fmt = ' and '.join(missing)
            _message = 'You need the **{}** permission(s) to use this command.'.format(fmt)
            await ctx.send(_message)
            return

        if isinstance(error, commands.UserInputError):
            await ctx.send("Invalid input.")
            await self.send_command_help(ctx)
            return

        if isinstance(error, commands.NoPrivateMessage):
            try:
                await ctx.author.send('This command cannot be used in direct messages.')
            except discord.Forbidden:
                pass
            return

        if isinstance(error, commands.CheckFailure):
            await ctx.send("You do not have permission to use this command.")
            return
        else:
            await ctx.send(f"{ctx.author.mention} Sorry, I encountered an unexpected error ;c")

        # ignore all other exception types, but print them to stderr
        print('Ignoring exception in command {}:'.format(ctx.command), file=sys.stderr)

        traceback.print_exception(type(error), error, error.__traceback__, file=sys.stderr)

        

async def setup(bot: commands.Bot):
    await bot.add_cog(ErrorHandler(bot))